Workbook
Name aaaa: #REF!
Name cause: #REF!
Name Comments: #REF!
Name DD: #REF!
Name DDD: #REF!
Name DDDDDDDD: #REF!
Name Domain: #REF!
Name Ltst_TestLog: "'Test log'"
Name NullOption: #REF!
Name Severity: #REF!
Name StartPoint: #REF!
Name State_of_Origin: #REF!
Name SW: #REF!
Name ValidDepts2: [1]Dropdown용!$A$1:$A$2
Name 기능: #REF!
Name 기능: #REF!
Name 난이도: #REF!
Name 난이도: #REF!
Name 변경여부: #REF!
Name 변경여부: #REF!
Name 분류: #REF!
Name 속성유형: #REF!
Name 수정여부: [2]기준표!$A$10:$A$14
Name 작업상태: #REF!
Name 적용여부: [2]기준표!$A$4:$A$6
Name 중요도: #REF!
Name 추가변경여부: #REF!
Name 카드관리부서: #REF!
Name 카드캐피탈구분: #REF!
Name 캐피탈관리부서: #REF!

Sheet 설비모델정의
A1: 자재코드 | B1: 자재명 | C1: 모델명 | D1: 분류 | E1: Rack/Shelf | F1: Height (Rack Unit) | G1: WIDTH (inch) | H1: WIDTH (mm) | I1: DEPTH (mm) | J1: HEIGHT (mm) | K1: NTOSS 정보 | L1: 소모전력 | M1: 무게(kg) | N1: 제조사 spec
A2: 581684 | B2: UTRANS-1664_SHELF | C2: UTRANS-1664 | D2: =VLOOKUP(A2,[3]박달_모장비!F:I,3,0) -> 10G | E2: Shelf | F2: 13 | G2: 23 | H2: =G2*25.4 -> 584.2 | I2: 520 | K2: =VLOOKUP(A2,[4]ntoss자재!B:D,3,0) -> 0 | L2: 750w | N2: 23Inch * 13U * 520mm
A3: 580307 | B3: C-MUX_COT_SHELF | C3: C-MUX_COT | D3: =VLOOKUP(A3,[3]박달_모장비!F:I,3,0) -> 51M | E3: Shelf | F3: 3 | G3: 19 | H3: =G3*25.4 -> 482.6 | I3: 357 | J3: 132 | K3: =VLOOKUP(A3,[4]ntoss자재!B:D,3,0) -> 0 | L3: 200w | N3: 482(W)*357(D)*132(H)mm,3U
A4: 580876 | B4: [진부화]SC-MUX_Shelf,COT | C4: SC-MUX | D4: =VLOOKUP(A4,[3]박달_모장비!F:I,3,0) -> 51M | E4: Shelf | F4: 3 | H4: 483 | I4: 310 | J4: 132 | K4: =VLOOKUP(A4,[4]ntoss자재!B:D,3,0) -> 0
A5: 580918 | B5: UTRANS-155M_SHELF | C5: UTRANS-155M | D5: =VLOOKUP(A5,[3]박달_모장비!F:I,3,0) -> 622M | E5: Shelf | F5: 3 | G5: 19 | H5: =G5*25.4 -> 482.6 | K5: =VLOOKUP(A5,[4]ntoss자재!B:D,3,0) -> 0
A6: 581765 | B6: [진부화]UTRANS-155V_SHELF_155V | C6: UTRANS-155V | D6: =VLOOKUP(A6,[3]박달_모장비!F:I,3,0) -> 622M | E6: Shelf | F6: 3 | G6: 19 | H6: =G6*25.4 -> 482.6
A7: 811760 | B7: 5G광중계기MU(3.5G)v2삼성용ActiveDAS지원 | C7: 5G 광중계기 MU(3.5G) | D7: =VLOOKUP(A7,[3]박달_모장비!F:I,3,0) -> Active Das | E7: Shelf | F7: 1 | G7: 19 | H7: =G7*25.4 -> 482.6 | I7: 400 | J7: 44 | K7: =VLOOKUP(A7,[4]ntoss자재!B:D,3,0) -> W48*D40*H4.4
A8: 813668 | B8: AC분전반 디지털 전력 계측기_Accura 3500 | C8: AC분전반 디지털 전력 계측기_Accura 3500 | D8: =VLOOKUP(A8,[3]박달_모장비!F:I,3,0) -> AC분전반 | H8: 115 | I8: 113 | J8: 88 | K8: =VLOOKUP(A8,[4]ntoss자재!B:D,3,0) -> W11.5*D11.3*H8.8
A9: 520275 | B9: MPDP(HF-7500A) | C9: MPDP(HF-7500A)[P] | D9: =VLOOKUP(A9,[3]박달_모장비!F:I,3,0) -> AC분전반 | E9: Shelf | F9: 2 | G9: 19 | H9: 430 | I9: 285 | J9: 88 | K9: =VLOOKUP(A9,[4]ntoss자재!B:D,3,0) -> 0 | N9: 19” 430mm(폭) x 88mm(높이) x 285mm(깊이)
A10: 809512 | B10: PDR(직류분전반) 80회로 이중화_KRN | C10: PDR(직류분전반) 80회로 이중화_KRN | D10: =VLOOKUP(A10,[3]박달_모장비!F:I,3,0) -> DC분전반 | E10: Shelf | F10: 설비 | K10: =VLOOKUP(A10,[4]ntoss자재!B:D,3,0) -> 0
A11: 540056 | B11: PDR(48V/48회로) | C11: 이중화분전반,직류,IPD[P] | D11: =VLOOKUP(A11,[3]박달_모장비!F:I,3,0) -> DC분전반 | E11: Rack | F11: 설비 | K11: =VLOOKUP(A11,[4]ntoss자재!B:D,3,0) -> 이중화분전반, IPD
A12: 808822 | B12: HWI/5G GNB/DU/DU_SHELF(BBU5900) | C12: HWI/5G GNB/DU/DU_SHELF(BBU5900) | D12: =VLOOKUP(A12,[3]박달_모장비!F:I,3,0) -> DU | E12: Shelf | F12: 2 | G12: 23 | H12: =G12*25.4 -> 584.2 | I12: 440 | J12: 86 | K12: =VLOOKUP(A12,[4]ntoss자재!B:D,3,0) -> 600(W)X440(D)X235(H) | L12: 210 | N12: (H x W x D) 86 mm x 442 mm x 310 mm (3.39 in. x 17.40 in. x 12.20 in.)
A13: 812037 | B13: HWI/LTE eNB/DU/DU_SHELF(BBU5900)_LTE용 | C13: HWI/5G GNB/DU/DU_SHELF(BBU5900) | D13: =VLOOKUP(A13,[3]박달_모장비!F:I,3,0) -> DU | E13: Shelf | F13: 5 | G13: 23 | H13: =G13*25.4 -> 584.2 | I13: 440 | J13: 235 | K13: =VLOOKUP(A13,[4]ntoss자재!B:D,3,0) -> W600*D440*H235 | N13: 400 mm x 160 mm x 380 mm (15.75 in. x 6.30 in. x 14.96 in.)
A14: 804540 | B14: NKA/eNB/FSMF | C14: Nokia/DU/FSMF | D14: =VLOOKUP(A14,[3]박달_모장비!F:I,3,0) -> DU | E14: Shelf | F14: 3 | G14: 19 | H14: =G14*25.4 -> 482.6 | I14: 560 | J14: 133 | K14: =VLOOKUP(A14,[4]ntoss자재!B:D,3,0) -> 0 | M14: 10 | N14: (H*W*D) 133*492*560 10kg
A15: 809472 | B15: SSE/eNB/DU30 | C15: Samsung/DU30 | D15: =VLOOKUP(A15,[3]박달_모장비!F:I,3,0) -> DU | E15: Shelf | F15: 1 | G15: 19 | H15: =G15*25.4 -> 482.6 | I15: 385 | J15: 88 | K15: =VLOOKUP(A15,[4]ntoss자재!B:D,3,0) -> 메인카드+SHELF 434 × 385 × 88,
A16: 810245 | B16: SSE/5G gNB/DU50 | C16: SSE/5G gNB/DU50 | D16: =VLOOKUP(A16,[3]박달_모장비!F:I,3,0) -> DU | E16: Shelf | F16: 2 | G16: 19 | H16: =G16*25.4 -> 482.6 | I16: 385 | J16: 88 | K16: =VLOOKUP(A16,[4]ntoss자재!B:D,3,0) -> 메인카드+SHELF 434 × 385 × 88,
A17: 810673 | B17: SSE/5G gNB/DU50_무상 | C17: SSE/5G gNB/DU50_무상 | D17: =VLOOKUP(A17,[3]박달_모장비!F:I,3,0) -> DU | E17: Shelf | F17: 2 | G17: 19 | H17: =G17*25.4 -> 482.6 | I17: 385 | J17: 88 | K17: =VLOOKUP(A17,[4]ntoss자재!B:D,3,0) -> 메인카드+SHELF 434 × 385 × 88,
A18: 808668 | B18: HWI/5G GNB/Bank/Rack/IBC10-DC(VerB) | C18: HWI/5G GNB/Bank/Rack/IBC10-DC(VerB) | D18: =VLOOKUP(A18,[3]박달_모장비!F:I,3,0) -> GNB Rack | E18: Rack | F18: 44(rack) | G18: 23 | H18: =G18*25.4 -> 584.2 | I18: 600 | J18: 2000 | K18: =VLOOKUP(A18,[4]ntoss자재!B:D,3,0) -> 600(W)X600(D)X2000(H)
A19: 809086 | B19: SSE/5G gNB/Bank/Rack | C19: SSE/5G gNB/Bank/Rack | D19: =VLOOKUP(A19,[3]박달_모장비!F:I,3,0) -> GNB Rack | E19: Rack | F19: 44(rack) | G19: 23 | H19: =G19*25.4 -> 584.2 | I19: 600 | J19: 2000 | K19: =VLOOKUP(A19,[4]ntoss자재!B:D,3,0) -> 600 × 600 × 2000?, 130KG
A20: 580608 | B20: [진부화]허브_넷기어 24Port,10/100Base | C20: NetGear(24port) | D20: =VLOOKUP(A20,[3]박달_모장비!F:I,3,0) -> Hub | E20: Shelf | F20: 1 | K20: =VLOOKUP(A20,[4]ntoss자재!B:D,3,0) -> 24PORT,10/100BASE
A21: 804571 | B21: [단종][진부화]USOR/MasterShelf | C21: USOR/MasterShelf | D21: =VLOOKUP(A21,[3]박달_모장비!F:I,3,0) -> MasterShelf/Unit/광모듈 | E21: Shelf | K21: =VLOOKUP(A21,[4]ntoss자재!B:D,3,0) -> 0
A22: 804704 | B22: [단종]통합광중계기용MasteShelf | C22: 통합광중계기용MasteShelf | D22: =VLOOKUP(A22,[3]박달_모장비!F:I,3,0) -> MasterShelf/Unit/광모듈 | E22: Shelf | K22: =VLOOKUP(A22,[4]ntoss자재!B:D,3,0) -> 0
A23: 377473 | B23: NE40E-X8_CR5P-08BASD-70 | C23: NE40E-X8 | D23: =VLOOKUP(A23,[3]박달_모장비!F:I,3,0) -> MPLS | E23: Shelf | F23: 14 | G23: 19 | H23: 620 | I23: 650 | J23: 442 | K23: =VLOOKUP(A23,[4]ntoss자재!B:D,3,0) -> 0 | L23: 4100 | M23: 240 | N23: 620 * 442 * 650 mm (14 U)
A24: 580118 | B24: 광분배함,가입자시설,MOFD SHELF | C24: MOFD SHELF | D24: =VLOOKUP(A24,[3]박달_모장비!F:I,3,0) -> OFD(core) | E24: Shelf | F24: 1 | K24: =VLOOKUP(A24,[4]ntoss자재!B:D,3,0) -> OJC포함(SC/APC)*2C,FC/OFA*2EA
A25: 582111 | B25: 광분배함,MOFD,Shelf (FC/PC타입) | C25: MOFD(FC/PC타입)[P] | D25: =VLOOKUP(A25,[3]박달_모장비!F:I,3,0) -> OFD(core) | E25: Shelf | F25: 1 | K25: =VLOOKUP(A25,[4]ntoss자재!B:D,3,0) -> 12C,OJC포함
A26: 581844 | B26: 광분배함,MOFD,RACK,2000H | C26: MOFD,RACK,2000H(OFS포함)[P] | D26: =VLOOKUP(A26,[3]박달_모장비!F:I,3,0) -> OFD(core) | E26: Shelf | F26: rack | H26: 700 | I26: 750 | J26: 2000 | K26: =VLOOKUP(A26,[4]ntoss자재!B:D,3,0) -> H2000*W700*D750
A27: 580371 | B27: 광분배함,MOFD,RACK,1800H | C27: 광분배함,MOFD,Rack(1800)[P] | D27: =VLOOKUP(A27,[3]박달_모장비!F:I,3,0) -> OFD(core) | E27: Shelf | F27: rack | H27: 700 | I27: 750 | J27: 1800 | K27: =VLOOKUP(A27,[4]ntoss자재!B:D,3,0) -> H1800*W700*D750
A28: 581883 | B28: EPON장비,OLT,U9024A-DC,공통부(유비쿼스) | C28: U9024A | D28: =VLOOKUP(A28,[3]박달_모장비!F:I,3,0) -> OLT | E28: Shelf | F28: 4 | G28: 19 | H28: =G28*25.4 -> 482.6 | I28: 300 | J28: 177 | K28: =VLOOKUP(A28,[4]ntoss자재!B:D,3,0) -> 20PORT PON, 4PORT GBE | L28: 164 | N28: 482.6mm(W) * 300mm(D) * 177mm(H)
A29: 810361 | B29: U9532H_chassis | C29: U9532H | D29: =VLOOKUP(A29,[3]박달_모장비!F:I,3,0) -> OLT | E29: Shelf | F29: 9 | G29: 19 | H29: =G29*25.4 -> 482.6 | I29: 220 | K29: =VLOOKUP(A29,[4]ntoss자재!B:D,3,0) -> 437MM × 407MM × 220MM
A30: 581526 | B30: V5724G_Chassis | C30: V5724G | D30: =VLOOKUP(A30,[3]박달_모장비!F:I,3,0) -> OLT | E30: Shelf | F30: 6 | G30: 19 | H30: 440 | I30: 221.5 | J30: 255 | N30: 440 x 255 x 221.5 mm (W x H x D)
A31: 802747 | B31: [단종]V8500_Chassis | C31: V8500 | D31: =VLOOKUP(A31,[3]박달_모장비!F:I,3,0) -> OLT | E31: Shelf | F31: 12 | G31: 19 | H31: 482 | I31: 242 | J31: 532 | K31: =VLOOKUP(A31,[4]ntoss자재!B:D,3,0) -> 19" CHASSIS WITH FRONT ACCESS 14 | N31: 482 x 532 x 242 mm 크기 (W x H x D)
A32: 377447 | B32: M2200-SHELF | C32: M2200 | D32: =VLOOKUP(A32,[3]박달_모장비!F:I,3,0) -> PB | E32: Shelf | F32: 1 | G32: 19
A33: 812529 | B33: NOKIA7210SAS-S_24F4SFP+(DC -48) | C33: 7210 SAS-S | D33: =VLOOKUP(A33,[3]박달_모장비!F:I,3,0) -> PTS | E33: Shelf | F33: 6 | H33: 440 | I33: 387 | J33: 432 | K33: =VLOOKUP(A33,[4]ntoss자재!B:D,3,0) -> W44.0*D38.7*H43.2
A34: 807306 | B34: UTRANS-7320_SHELF | C34: UTRANS-7320 | D34: =VLOOKUP(A34,[3]박달_모장비!F:I,3,0) -> PTS | E34: Shelf | F34: 6 | G34: 19 | H34: =G34*25.4 -> 482.6 | I34: 400 | J34: =F34*44 -> 264 | K34: =VLOOKUP(A34,[4]ntoss자재!B:D,3,0) -> UTRANS-7320 SHELF | N34: 19” x 6RU x 400mm (W x H x D)
A35: 801730 | B35: UTRANS-7400_SHELF | C35: UTRANS-7400 | D35: =VLOOKUP(A35,[3]박달_모장비!F:I,3,0) -> PTS | E35: Shelf | F35: 1 | G35: 19 | H35: =G35*25.4 -> 482.6 | I35: 310 | J35: 44 | K35: =VLOOKUP(A35,[4]ntoss자재!B:D,3,0) -> 0 | N35: 19” x 1RU x 310mm (W x H x D)
A36: 809468 | B36: SSE/eNB/Bank/Rack(PDP포함) | C36: SSE/eNB/Bank/Rack(PDP포함) | D36: =VLOOKUP(A36,[3]박달_모장비!F:I,3,0) -> Rack | E36: Rack | F36: 44(rack) | G36: 23 | H36: =G36*25.4 -> 584.2 | I36: 600 | J36: 2000 | K36: =VLOOKUP(A36,[4]ntoss자재!B:D,3,0) -> 600 × 600 × 2000?, 130KG | M36: 130
A37: 809745 | B37: SSE/5G 광중계기/RIU/3.5G_8TRX | C37: SSE/5G 광중계기/RIU/3.5G_8TRX | D37: =VLOOKUP(A37,[3]박달_모장비!F:I,3,0) -> RIU | F37: 1 | H37: 434 | I37: 385 | J37: 43 | K37: =VLOOKUP(A37,[4]ntoss자재!B:D,3,0) -> 434MM * 43.6MM * 385MM, 7KG | M37: 7
A38: 802201 | B38: 광MUX(무선) | C38: Optical MUX(xHaul) | D38: =VLOOKUP(A38,[3]박달_모장비!F:I,3,0) -> RN/Splitter | F38: 3 | K38: =VLOOKUP(A38,[4]ntoss자재!B:D,3,0) -> 0
A39: 807048 | B39: E8013_Chassis | C39: E8013 | D39: =VLOOKUP(A39,[3]박달_모장비!F:I,3,0) -> Router | F39: 20 | G39: 18 | H39: 440 | I39: 567 | J39: 885 | K39: =VLOOKUP(A39,[4]ntoss자재!B:D,3,0) -> E8013, 4T, 13MODULAR (2PFC+1FC+1 | N39: W(440) * D(567) * H(885) mm, 20 RU
A40: 808912 | B40: NE40E-X8A_Chassis | C40: NE40E-X8A | D40: =VLOOKUP(A40,[3]박달_모장비!F:I,3,0) -> Router | F40: 21 | K40: =VLOOKUP(A40,[4]ntoss자재!B:D,3,0) -> W93*D44.2*H75
...

Sheet Rack모델
K1: RU ? | L1: 참고
B2: 모델명 | C2: 제조사 | D2: 크기 | E2: Unit | F2: 종류 | G2: 등록일자 | H2: Height | I2: Depth | J2: Width | L2: RU=(height-200)/44.45
B3: 국사 | C3: 기본 | D3: H1800 X D750 X W600 mm | E3: 36 | F3: 19“ | G3: 45505 | H3: 1800 | I3: 750 | J3: 600 | K3: 36 | L3: =(H3-200)/44.45 -> 35.995501
D4: H2000 X D750 X W600 mm | E4: 40 | G4: 45505 | H4: 2000 | I4: 750 | J4: 600 | K4: 40 | L4: =(H4-200)/44.45 -> 40.494938
D5: H2200 X D750 X W600 mm | E5: 44 | G5: 45505 | H5: 2200 | I5: 750 | J5: 600 | K5: 44 | L5: =(H5-200)/44.45 -> 44.994376
D6: H2200 X D900 X W600 mm | E6: 44 | G6: 45505 | H6: 2200 | I6: 900 | J6: 600 | K6: 44 | L6: =(H6-200)/44.45 -> 44.994376
B7: 기업자 | D7: H395 X D500 X W580 mm | E7: 4 | F7: 19“ | G7: 45505 | H7: 395 | I7: 500 | J7: 580 | K7: 4 | L7: =(H7-200)/44.45 -> 4.3869516
D8: H575 X D450 X W200 mm | E8: 8 | G8: 45505 | H8: 575 | I8: 450 | J8: 200 | K8: 8 | L8: =(H8-200)/44.45 -> 8.4364454
D9: H525 X D800 X W580 mm | E9: 8 | G9: 45505 | H9: 525 | I9: 800 | J9: 580 | K9: 8 | L9: =(H9-200)/44.45 -> 7.3115861
D10: H750 X D800 X W600 mm | E10: 12 | G10: 45505 | H10: 750 | I10: 800 | J10: 600 | K10: 12 | L10: =(H10-200)/44.45 -> 12.373453
D11: H525 X D500 X W580 mm | E11: 8 | G11: 45505 | H11: 525 | I11: 500 | J11: 580 | K11: 8 | L11: =(H11-200)/44.45 -> 7.3115861
D12: H750 X D600 X W600 mm | E12: 12 | G12: 45505 | H12: 750 | I12: 600 | J12: 600 | K12: 12 | L12: =(H12-200)/44.45 -> 12.373453
D13: H1200 X D750 X W600 mm | E13: 22 | G13: 45505 | H13: 1200 | I13: 750 | J13: 600 | K13: 22 | L13: =(H13-200)/44.45 -> 22.497188
D14: H1800 X D750 X W600 mm | E14: 36 | G14: 45505 | H14: 1800 | I14: 750 | J14: 600 | K14: 36 | L14: =(H14-200)/44.45 -> 35.995501
D15: H2000 X D750 X W600 mm | E15: 40 | G15: 45505 | H15: 2000 | I15: 750 | J15: 600 | K15: 40 | L15: =(H15-200)/44.45 -> 40.494938
D16: H2200 X D750 X W600 mm | E16: 40 | G16: 45505 | H16: 2200 | I16: 750 | J16: 600 | K16: 40 | L16: =(H16-200)/44.45 -> 44.994376
D17: H750 X D600 X W600 mm | E17: 12 | G17: 45505 | H17: 750 | I17: 600 | J17: 600 | K17: 12 | L17: =(H17-200)/44.45 -> 12.373453
D18: H1200 X D750 X W600 mm | E18: 22 | G18: 45505 | H18: 1200 | I18: 750 | J18: 600 | K18: 22 | L18: =(H18-200)/44.45 -> 22.497188
D19: H1800 X D750 X W600 mm | E19: 36 | G19: 45505 | H19: 1800 | I19: 750 | J19: 600 | K19: 36 | L19: =(H19-200)/44.45 -> 35.995501
... D23: H2200 X D750 X W600 mm | E23: 44 | G23: 45505 | H23: 2200 | I23: 750 | J23: 600 | K23: 44 | L23: =(H23-200)/44.45 -> 44.994376
D24: H2000 X D750 X W600 mm | E24: 40 | G24: 45505 | H24: 2000 | I24: 750 | J24: 600 | K24: 40 | L24: =(H24-200)/44.45 -> 40.494938
D25: H395 X D560 X W560 mm | E25: 4 | G25: 45505 | H25: 395 | I25: 560 | J25: 560 | K25: 4 | L25: =(H25-200)/44.45 -> 4.3869516
D26: H525 X D560 X W560 mm | E26: 8 | G26: 45505 | H26: 525 | I26: 560 | J26: 560 | K26: 8 | L26: =(H26-200)/44.45 -> 7.3115861
D27: H750 X D560 X W560 mm | E27: 12 | G27: 45505 | H27: 750 | I27: 560 | J27: 560 | K27: 12 | L27: =(H27-200)/44.45 -> 12.373453
B28: 광랜 | D28: H500 X D500 X W600 mm | E28: 8 | F28: 19“ | G28: 45505 | H28: 500 | I28: 500 | J28: 600 | K28: 8 | L28: =(H28-200)/44.45 -> 6.7491564
D29: H600 X D600 X W600 mm | E29: 10 | G29: 45505 | H29: 600 | I29: 600 | J29: 600 | K29: 10 | L29: =(H29-200)/44.45 -> 8.9988751
D30: H700 X D700 X W600 mm | E30: 12 | G30: 45505 | H30: 700 | I30: 700 | J30: 600 | K30: 12 | L30: =(H30-200)/44.45 -> 11.248594
D31: H600 X D300 X W600 mm | E31: 10 | G31: 45505 | H31: 600 | I31: 300 | J31: 600 | K31: 10 | L31: =(H31-200)/44.45 -> 8.9988751
D32: H600 X D250 X W500 mm | E32: 10 | G32: 45505 | H32: 600 | I32: 250 | J32: 500 | K32: 10 | L32: =(H32-200)/44.45 -> 8.9988751
B33: 가입자 | D33: H2200 X D750 X W600 mm | E33: 44 | F33: 23” | G33: 45505 | H33: 2200 | I33: 750 | J33: 600 | K33: 44 | L33: =(H33-200)/44.45 -> 44.994376
